Workbook

Sheet Cover Page
D2: RateGain | K2: Unlock New Revenue Everyday
E7: Scenario Analysis Model
E11: Table of Content
E13: {=RIGHT(CELL("filename",A1),LEN(CELL("filename",A1))-FIND("]",CELL("filename",A1)))} -> Cover Page
E14: {=RIGHT(CELL("filename",'Exeutive Dashboard'!A2),LEN(CELL("filename",'Exeutive Dashboard'!A2))-FIND("]",CELL("filename",'Exeutive Dashboard'!A2)))} -> Exeutive Dashboard
E15: {=RIGHT(CELL("filename",'12 Month Rolling Forecast'!A3),LEN(CELL("filename",'12 Month Rolling Forecast'!A3))-FIND("]",CELL("filename",'12 Month Rolling Forecast'!A4)))} -> 12 Month Rolling Forecast
E16: {=RIGHT(CELL("filename",'Assumptions & Data'!A1),LEN(CELL("filename",'Assumptions & Data'!A1))-FIND("]",(CELL("filename",'Assumptions & Data'!A1))))} -> Assumptions & Data
BV79: Page

Sheet Exeutive Dashboard
H3: Scenario Selector | I3: Upside
A5: EXECUTIVE DASHBOARD
A6: Indian Rupee ₹
A7: Metric | B7: Current | C7: Month 12 | E7: KPIs | F7: Status
A8: MRR | B8: ='12 Month Rolling Forecast'!D18 -> 450000000 | C8: ='12 Month Rolling Forecast'!P18 -> 7.6895383e+08 | E8: LTV:CAC Ratio | F8: =IF(Q45>=3,"✓ Healthy",IF(Q45>=1,"⚠ Needs Improvement","✗ Critical")) -> ✗ Critical
A9: ARR | B9: ='12 Month Rolling Forecast'!D19 -> 5281800000 | C9: ='12 Month Rolling Forecast'!P19 -> 9.227446e+09 | E9: Burn Multiple | F9: =IF( '12 Month Rolling Forecast'!Q37/'12 Month Rolling Forecast'!Q17<=2, "✓ Efficient", IF( '12 Month Rolling Forecast'!Q37/'12 Month Rolling Forecast'!Q17<4, "⚠ Monitor", "✗ High Burn" ) ) -> ✓ Efficient
A10: Customers | B10: ='12 Month Rolling Forecast'!D9 -> 774 | C10: ='12 Month Rolling Forecast'!P9 -> 1116 | E10: Gross Margin | F10: =IF('12 Month Rolling Forecast'!Q43>=0.7,"✓ Healthy",IF('12 Month Rolling Forecast'!Q43>=0.5,"⚠ Low","✗ Critical")) -> ✓ Healthy
A11: Monthly Burn | B11: ='12 Month Rolling Forecast'!D37 -> -17600000 | C11: ='12 Month Rolling Forecast'!P37 -> 0 | E11: Churn Rate | F11: =IF('12 Month Rolling Forecast'!Q52<=0.02,"✓ Low",IF('12 Month Rolling Forecast'!Q52<=0.05,"⚠ Moderate","✗ High")) -> ✓ Low
A12: Cash Balance | B12: ='12 Month Rolling Forecast'!D35 -> 2225877600 | C12: ='12 Month Rolling Forecast'!P35 -> 3.8207112e+09 | E12: Quick Ratio | F12: =IF('12 Month Rolling Forecast'!Q54>=4,"✓ Strong",IF('12 Month Rolling Forecast'!Q54>=2,"⚠ Moderate","✗ Weak")) -> ✓ Strong
A13: Runway (month) | B13: ='12 Month Rolling Forecast'!D56 -> 126.47032 | C13: ='12 Month Rolling Forecast'!P56 -> Cash Positive
A15: 12 Months Summary
A16: Total Revenue | B16: ='12 Month Rolling Forecast'!Q23 -> 7.5099115e+09 | E16: Funding Trigger
A17: Total EBITDA | B17: ='12 Month Rolling Forecast'!Q27 -> 2.2844336e+09 | E17: Raise needed when runway < 6 months
A18: Net Cash Surplus (Used) | B18: ='12 Month Rolling Forecast'!Q34 -> 1.5948336e+09 | E18: Current Status: | F18: =IF('12 Month Rolling Forecast'!D56<6,"⚠ START FUNDRAISING NOW","✓ Runway OK") -> ✓ Runway OK
A19: Avg Burn Multiple | B19: ='12 Month Rolling Forecast'!Q37/'12 Month Rolling Forecast'!Q17 -> 0

Sheet 12 Month Rolling Forecast
A1: RateGain | C1: Actuals --> | E1: Forecast -->
A2: Indian Rupee ₹ | C2: 45716 | D2: =EOMONTH(C2,1) -> 45747 | E2: =EOMONTH(D2,1) -> 45777 | F2: =EOMONTH(E2,1) -> 45808 | G2: =EOMONTH(F2,1) -> 45838 | H2: =EOMONTH(G2,1) -> 45869 | I2: =EOMONTH(H2,1) -> 45900 | J2: =EOMONTH(I2,1) -> 45930 | K2: =EOMONTH(J2,1) -> 45961 | ... P2: =EOMONTH(O2,1) -> 46112 | Q2: TOTAL
A5: CUSTOMER METRICS
A6: Beginning Customers | C6: 740 | D6: =C9 -> 756 | E6: =D9 -> 774 | F6: =E9 -> 803 | G6: =F9 -> 833 | H6: =G9 -> 862 | I6: =H9 -> 891 | J6: =I9 -> 920 | K6: =J9 -> 949 | ... P6: =O9 -> 1089 | Q6: -
A7: New Customers | C7: 20 | D7: 22 | E7: ='Assumptions & Data'!$B$90 -> 35 | F7: =ROUND(E7*(1+'Assumptions & Data'!B91),0) -> 36 | G7: =ROUND(F7*(1+'Assumptions & Data'!C91),0) -> 36 | H7: =ROUND(G7*(1+'Assumptions & Data'!D91),0) -> 36 | I7: =ROUND(H7*(1+'Assumptions & Data'!E91),0) -> 36 | J7: =ROUND(I7*(1+'Assumptions & Data'!F91),0) -> 36 | K7: =ROUND(J7*(1+'Assumptions & Data'!G91),0) -> 36 | L7: =ROUND(K7*(1+'Assumptions & Data'!H91),0) -> 36 | M7: =ROUND(L7*(1+'Assumptions & Data'!I91),0) -> 36 | ... P7: =ROUND(O7*(1+'Assumptions & Data'!L91),0) -> 36 | Q7: =SUM(E7:P7) -> 431
A8: Churned Customers | C8: -4 | D8: -4 | E8: =-ROUND(E6*'Assumptions & Data'!$B$93,0) -> -6 | F8: =-ROUND(F6*'Assumptions & Data'!$B$93,0) -> -6 | G8: =-ROUND(G6*'Assumptions & Data'!$B$93,0) -> -7 | H8: =-ROUND(H6*'Assumptions & Data'!$B$93,0) -> -7 | I8: =-ROUND(I6*'Assumptions & Data'!$B$93,0) -> -7 | J8: =-ROUND(J6*'Assumptions & Data'!$B$93,0) -> -7 | K8: =-ROUND(K6*'Assumptions & Data'!$B$93,0) -> -8 | L8: =-ROUND(L6*'Assumptions & Data'!$B$93,0) -> -8 | ... P8: =-ROUND(P6*'Assumptions & Data'!$B$93,0) -> -9 | Q8: =SUM(E8:P8) -> -89
A9: Ending Customers | C9: =SUM(C6:C8) -> 756 | D9: =SUM(D6:D8) -> 774 | E9: =SUM(E6:E8) -> 803 | F9: =SUM(F6:F8) -> 833 | G9: =SUM(G6:G8) -> 862 | H9: =SUM(H6:H8) -> 891 | I9: =SUM(I6:I8) -> 920 | J9: =SUM(J6:J8) -> 949 | ... P9: =SUM(P6:P8) -> 1116 | Q9: =P9 -> 1116
A12: REVENUE METRICS
A13: Beginning MRR | C13: 420000000 | D13: =C18 -> 429830000 | E13: ='Assumptions & Data'!$B$89 -> 460000000 | F13: =E18 -> 484590000 | G13: =F18 -> 509928360 | H13: =G18 -> 5.3536807e+08 | I13: =H18 -> 5.6090955e+08 | J13: =I18 -> 5.8655318e+08 | K13: =J18 -> 6.122994e+08 | L13: =K18 -> 6.3814859e+08 | M13: =L18 -> 6.6410119e+08 | ... P13: =O18 -> 7.425835e+08 | Q13: -
A14: New MRR | C14: 10000000 | D14: 10500000 | E14: ='12 Month Rolling Forecast'!E7*'Assumptions & Data'!$B$92 -> 22750000 | F14: ='12 Month Rolling Forecast'!F7*'Assumptions & Data'!$B$92 -> 23400000 | G14: ='12 Month Rolling Forecast'!G7*'Assumptions & Data'!$B$92 -> 23400000 | H14: ='12 Month Rolling Forecast'!H7*'Assumptions & Data'!$B$92 -> 23400000 | I14: ='12 Month Rolling Forecast'!I7*'Assumptions & Data'!$B$92 -> 23400000 | J14: ='12 Month Rolling Forecast'!J7*'Assumptions & Data'!$B$92 -> 23400000 | K14: ='12 Month Rolling Forecast'!K7*'Assumptions & Data'!$B$92 -> 23400000 | L14: ='12 Month Rolling Forecast'!L7*'Assumptions & Data'!$B$92 -> 23400000 | ... P14: ='12 Month Rolling Forecast'!P7*'Assumptions & Data'!$B$92 -> 23400000 | Q14: =SUM(E14:P14) -> 280150000
A15: Expansion MRR | C15: 325000 | D15: 330000 | E15: =E13*'Assumptions & Data'!$B$94 -> 5520000 | F15: =F13*'Assumptions & Data'!$B$94 -> 5815080 | G15: =G13*'Assumptions & Data'!$B$94 -> 6119140.3 | H15: =H13*'Assumptions & Data'!$B$94 -> 6424416.9 | I15: =I13*'Assumptions & Data'!$B$94 -> 6730914.5 | J15: =J13*'Assumptions & Data'!$B$94 -> 7038638.2 | K15: =K13*'Assumptions & Data'!$B$94 -> 7347592.8 | L15: =L13*'Assumptions & Data'!$B$94 -> 7657783.1 | ... P15: =P13*'Assumptions & Data'!$B$94 -> 8911002 | Q15: =SUM(E15:P15) -> 86411492
A16: Churned MRR | C16: -495000 | D16: -510000 | E16: =-E13*'Assumptions & Data'!$B$93 -> -3680000 | F16: =-F13*'Assumptions & Data'!$B$93 -> -3876720 | G16: =-G13*'Assumptions & Data'!$B$93 -> -4079426.9 | H16: =-H13*'Assumptions & Data'!$B$93 -> -4282944.6 | I16: =-I13*'Assumptions & Data'!$B$93 -> -4487276.4 | J16: =-J13*'Assumptions & Data'!$B$93 -> -4692425.5 | K16: =-K13*'Assumptions & Data'!$B$93 -> -4898395.2 | L16: =-L13*'Assumptions & Data'!$B$93 -> -5105188.8 | ... P16: =-P13*'Assumptions & Data'!$B$93 -> -5940668 | Q16: =SUM(E16:P16) -> -57607661
A17: Net New MRR | C17: 9830000 | D17: 10320000 | E17: =SUM(E14:E16) -> 24590000 | F17: =SUM(F14:F16) -> 25338360 | G17: =SUM(G14:G16) -> 25439713 | H17: =SUM(H14:H16) -> 25541472 | I17: =SUM(I14:I16) -> 25643638 | J17: =SUM(J14:J16) -> 25746213 | K17: =SUM(K14:K16) -> 25849198 | L17: =SUM(L14:L16) -> 25952594 | ... P17: =SUM(P14:P16) -> 26370334 | Q17: =SUM(E17:P17) -> 3.0895383e+08
A18: Ending MRR | C18: 429830000 | D18: 450000000 | E18: =E13+E17 -> 484590000 | F18: =F13+F17 -> 509928360 | G18: =G13+G17 -> 5.3536807e+08 | H18: =H13+H17 -> 5.6090955e+08 | I18: =I13+I17 -> 5.8655318e+08 | J18: =J13+J17 -> 6.122994e+08 | K18: =K13+K17 -> 6.3814859e+08 | L18: =L13+L17 -> 6.6410119e+08 | ... P18: =P13+P17 -> 7.6895383e+08 | Q18: =P18 -> 7.6895383e+08
A19: ARR | C19: 5157960000 | D19: 5281800000 | E19: =E18*12 -> 5815080000 | F19: =F18*12 -> 6119140320 | G19: =G18*12 -> 6.4244169e+09 | H19: =H18*12 -> 6.7309145e+09 | I19: =I18*12 -> 7.0386382e+09 | J19: =J18*12 -> 7.3475928e+09 | K19: =K18*12 -> 7.6577831e+09 | L19: =L18*12 -> 7.9692143e+09 | ... Q19: =Q18*12 -> 9.227446e+09
A22: P&L SUMMARY
A23: Revenue (MRR) | C23: 429830000 | D23: 450000000 | E23: =E18 -> 484590000 | F23: =F18 -> 509928360 | G23: =G18 -> 5.3536807e+08 | H23: =H18 -> 5.6090955e+08 | I23: =I18 -> 5.8655318e+08 | J23: =J18 -> 6.122994e+08 | K23: =K18 -> 6.3814859e+08 | L23: =L18 -> 6.6410119e+08 | ... P23: =P18 -> 7.6895383e+08 | Q23: =SUM(E23:P23) -> 7.5099115e+09
A24: Cost of Revenue (COGS) | C24: -1.203524e+08 | D24: -1.26e+08 | E24: =-E23*(1-'Assumptions & Data'!$B$95) -> -121147500 | F24: =-F23*(1-'Assumptions & Data'!$B$95) -> -127482090 | G24: =-G23*(1-'Assumptions & Data'!$B$95) -> -1.3384202e+08 | H24: =-H23*(1-'Assumptions & Data'!$B$95) -> -1.4022739e+08 | I24: =-I23*(1-'Assumptions & Data'!$B$95) -> -1.466383e+08 | J24: =-J23*(1-'Assumptions & Data'!$B$95) -> -1.5307485e+08 | K24: =-K23*(1-'Assumptions & Data'!$B$95) -> -1.5953715e+08 | L24: =-L23*(1-'Assumptions & Data'!$B$95) -> -1.660253e+08 | ... P24: =-P23*(1-'Assumptions & Data'!$B$95) -> -1.9223846e+08 | Q24: =SUM(E24:P24) -> -1.8774779e+09
A25: Gross Profit | C25: 309477600 | D25: 324000000 | E25: =SUM(E23:E24) -> 363442500 | F25: =SUM(F23:F24) -> 382446270 | G25: =SUM(G23:G24) -> 4.0152606e+08 | H25: =SUM(H23:H24) -> 4.2068216e+08 | I25: =SUM(I23:I24) -> 4.3991489e+08 | J25: =SUM(J23:J24) -> 4.5922455e+08 | K25: =SUM(K23:K24) -> 4.7861145e+08 | L25: =SUM(L23:L24) -> 4.9807589e+08 | ... P25: =SUM(P23:P24) -> 5.7671537e+08 | Q25: =SUM(E25:P25) -> 5.6324336e+09
A26: Operating Expenses | C26: -302000000 | D26: -302000000 | E26: =-'Assumptions & Data'!$B$110 -> -279000000 | F26: =-'Assumptions & Data'!$B$110 -> -279000000 | G26: =-'Assumptions & Data'!$B$110 -> -279000000 | H26: =-'Assumptions & Data'!$B$110 -> -279000000 | I26: =-'Assumptions & Data'!$B$110 -> -279000000 | J26: =-'Assumptions & Data'!$B$110 -> -279000000 | K26: =-'Assumptions & Data'!$B$110 -> -279000000 | L26: =-'Assumptions & Data'!$B$110 -> -279000000 | ... P26: =-'Assumptions & Data'!$B$110 -> -279000000 | Q26: =SUM(E26:P26) -> -3348000000
A27: EBITDA | C27: 7477600 | D27: 22000000 | E27: =SUM(E25:E26) -> 84442500 | F27: =SUM(F25:F26) -> 103446270 | G27: =SUM(G25:G26) -> 1.2252606e+08 | H27: =SUM(H25:H26) -> 1.4168216e+08 | I27: =SUM(I25:I26) -> 1.6091489e+08 | J27: =SUM(J25:J26) -> 1.8022455e+08 | K27: =SUM(K25:K26) -> 1.9961145e+08 | L27: =SUM(L25:L26) -> 2.1907589e+08 | ... P27: =SUM(P25:P26) -> 2.9771537e+08 | Q27: =SUM(E27:P27) -> 2.2844336e+09
A30: CASH FLOW & RUNWAY
A31: Beginning Cash | C31: 2200000000 | D31: 2243477600 | E31: =D35 -> 2225877600 | F31: =E35 -> 2254320100 | G31: =F35 -> 2300166370 | H31: =G35 -> 2.3650924e+09 | I31: =H35 -> 2.4491746e+09 | J31: =I35 -> 2.5524895e+09 | K31: =J35 -> 2.675114e+09 | L31: =K35 -> 2.8171255e+09 | ... P31: =O35 -> 3.5805958e+09 | Q31: =E31 -> 2225877600
A32: Cash from Operations (EBITDA) | C32: 7477600 | D32: 22000000 | E32: =E27 -> 84442500 | F32: =F27 -> 103446270 | G32: =G27 -> 1.2252606e+08 | H32: =H27 -> 1.4168216e+08 | I32: =I27 -> 1.6091489e+08 | J32: =J27 -> 1.8022455e+08 | K32: =K27 -> 1.9961145e+08 | L32: =L27 -> 2.1907589e+08 | ... P32: =P27 -> 2.9771537e+08 | Q32: =SUM(E32:P32) -> 2.2844336e+09
A33: CAC Investment | C33: -36000000 | D33: -39600000 | E33: =-E7*'Assumptions & Data'!$B$96 -> -56000000 | F33: =-F7*'Assumptions & Data'!$B$96 -> -57600000 | G33: =-G7*'Assumptions & Data'!$B$96 -> -57600000 | H33: =-H7*'Assumptions & Data'!$B$96 -> -57600000 | I33: =-I7*'Assumptions & Data'!$B$96 -> -57600000 | J33: =-J7*'Assumptions & Data'!$B$96 -> -57600000 | K33: =-K7*'Assumptions & Data'!$B$96 -> -57600000 | L33: =-L7*'Assumptions & Data'!$B$96 -> -57600000 | ... P33: =-P7*'Assumptions & Data'!$B$96 -> -57600000 | Q33: =SUM(E33:P33) -> -689600000
A34: Net Cash Flow | C34: -28522400 | D34: -17600000 | E34: =SUM(E32:E33) -> 28442500 | F34: =SUM(F32:F33) -> 45846270 | G34: =SUM(G32:G33) -> 64926055 | H34: =SUM(H32:H33) -> 84082159 | I34: =SUM(I32:I33) -> 1.0331489e+08 | J34: =SUM(J32:J33) -> 1.2262455e+08 | K34: =SUM(K32:K33) -> 1.4201145e+08 | L34: =SUM(L32:L33) -> 1.6147589e+08 | ... P34: =SUM(P32:P33) -> 2.4011537e+08 | Q34: =SUM(E34:P34) -> 1.5948336e+09
A35: Ending Cash | C35: 2171477600 | D35: 2225877600 | E35: =E34+E31 -> 2254320100 | F35: =F34+F31 -> 2300166370 | G35: =G34+G31 -> 2.3650924e+09 | H35: =H34+H31 -> 2.4491746e+09 | I35: =I34+I31 -> 2.5524895e+09 | J35: =J34+J31 -> 2.675114e+09 | K35: =K34+K31 -> 2.8171255e+09 | L35: =L34+L31 -> 2.9786014e+09 | ... P35: =P34+P31 -> 3.8207112e+09 | Q35: =P35 -> 3.8207112e+09
A37: Monthly Burn Rate | C37: -28522400 | D37: -17600000 | E37: =IF(E34<0,E34,0) -> 0 | F37: =IF(F34<0,F34,0) -> 0 | G37: =IF(G34<0,G34,0) -> 0 | H37: =IF(H34<0,H34,0) -> 0 | I37: =IF(I34<0,I34,0) -> 0 | J37: =IF(J34<0,J34,0) -> 0 | K37: =IF(K34<0,K34,0) -> 0 | L37: =IF(L34<0,L34,0) -> 0 | ... P37: =IF(P34<0,P34,0) -> 0 | Q37: =AVERAGE(E37:P37) -> 0
A40: Unit Economics
A41: CAC (Customer Acquisition Cost) | C41: 1800000 | D41: 1800000 | E41: ='Assumptions & Data'!$B$96 -> 1600000 | F41: ='Assumptions & Data'!$B$96 -> 1600000 | G41: ='Assumptions & Data'!$B$96 -> 1600000 | H41: ='Assumptions & Data'!$B$96 -> 1600000 | I41: ='Assumptions & Data'!$B$96 -> 1600000 | J41: ='Assumptions & Data'!$B$96 -> 1600000 | K41: ='Assumptions & Data'!$B$96 -> 1600000 | L41: ='Assumptions & Data'!$B$96 -> 1600000 | ... P41: ='Assumptions & Data'!$B$96 -> 1600000 | Q41: =AVERAGE(E41:P41) -> 1600000
A42: ARPA (Avg Revenue Per Account) | C42: 568558.2 | D42: 581395.35 | E42: =E18/E9 -> 603474.47 | F42: =F18/F9 -> 612158.9 | G42: =G18/G9 -> 621076.65 | H42: =H18/H9 -> 629528.11 | I42: =I18/I9 -> 637557.81 | J42: =J18/J9 -> 645204.84 | K42: =K18/K9 -> 653171.54 | L42: =L18/L9 -> 660797.2 | ... P42: =P18/P9 -> 689026.73 | Q42: =AVERAGE(E42:P42) -> 648094.67
A43: Gross Margin % | C43: 0.72 | D43: 0.72 | E43: ='Assumptions & Data'!$B$95 -> 0.75 | F43: ='Assumptions & Data'!$B$95 -> 0.75 | G43: ='Assumptions & Data'!$B$95 -> 0.75 | H43: ='Assumptions & Data'!$B$95 -> 0.75 | I43: ='Assumptions & Data'!$B$95 -> 0.75 | J43: ='Assumptions & Data'!$B$95 -> 0.75 | K43: ='Assumptions & Data'!$B$95 -> 0.75 | L43: ='Assumptions & Data'!$B$95 -> 0.75 | ... P43: ='Assumptions & Data'!$B$95 -> 0.75 | Q43: =AVERAGE(E43:P43) -> 0.75
A44: LTV (Lifetime Value) | C44: 34113492 | D44: 34883721 | E44: =E42*E43/('Assumptions & Data'!$B$93) -> 56575732 | F44: =F42*F43/('Assumptions & Data'!$B$93) -> 57389896 | G44: =G42*G43/('Assumptions & Data'!$B$93) -> 58225936 | H44: =H42*H43/('Assumptions & Data'!$B$93) -> 59018260 | I44: =I42*I43/('Assumptions & Data'!$B$93) -> 59771045 | J44: =J42*J43/('Assumptions & Data'!$B$93) -> 60487954 | K44: =K42*K43/('Assumptions & Data'!$B$93) -> 61234832 | L44: =L42*L43/('Assumptions & Data'!$B$93) -> 61949738 | ... P44: =P42*P43/('Assumptions & Data'!$B$93) -> 64596256 | Q44: =AVERAGE(E44:P44) -> 60758875
A45: LTV:CAC Ratio | C45: 18.95194 | D45: 19.379845 | E45: =E44/E41 -> 35.359832 | F45: =F44/F41 -> 35.868685 | G45: =G44/G41 -> 36.39121 | H45: =H44/H41 -> 36.886413 | I45: =I44/I41 -> 37.356903 | J45: =J44/J41 -> 37.804971 | K45: =K44/K41 -> 38.27177 | L45: =L44/L41 -> 38.718586 | ... P45: =P44/P41 -> 40.37266 | Q45: =AVERAGE(E45:P45) -> 37.974297
A46: CAC Payback (months) | C46: 4.3970872 | D46: 4.3 | E46: =E41/(E42*E43) -> 3.5350846 | F46: =F41/(F42*F43) -> 3.484934 | G46: =G41/(G42*G43) -> 3.4348954 | H46: =H41/(H42*H43) -> 3.3887817 | I46: =I41/(I42*I43) -> 3.3461018 | J46: =J41/(J42*J43) -> 3.3064435 | K46: =K41/(K42*K43) -> 3.266115 | L46: =L41/(L42*L43) -> 3.2284237 | ... P46: =P41/(P42*P43) -> 3.0961547 | Q46: =AVERAGE(E46:P46) -> 3.2973684
A49: Growth Metrics
A50: MRR Growth Rate (MoM) | C50: - | D50: =(D18-C18)/C18 -> 0.046925529 | E50: =(E18-D18)/D18 -> 0.076866667 | F50: =(F18-E18)/E18 -> 0.052288244 | G50: =(G18-F18)/F18 -> 0.049888799 | H50: =(H18-G18)/G18 -> 0.047708247 | I50: =(I18-H18)/H18 -> 0.045717956 | J50: =(J18-I18)/I18 -> 0.043894081 | K50: =(K18-J18)/J18 -> 0.042216598 | ... P50: =(P18-O18)/O18 -> 0.035511608 | Q50: =AVERAGE(E50:P50) -> 0.04571406
A51: Net Revenue Retention (NRR) | C51: =(C18+C15-C16)/C13 -> 1.0253571 | D51: =(D18+D15-D16)/D13 -> 1.0488798 | E51: =(E18+E15-E16)/E13 -> 1.0734565 | F51: =(F18+F15-F16)/F13 -> 1.0722882 | G51: =(G18+G15-G16)/G13 -> 1.0698888 | H51: =(H18+H15-H16)/H13 -> 1.0677082 | I51: =(I18+I15-I16)/I13 -> 1.065718 | J51: =(J18+J15-J16)/J13 -> 1.0638941 | ... P51: =(P18+P15-P16)/P13 -> 1.0555116 | Q51: =AVERAGE(E51:P51) -> 1.0637632
A52: Gross Churn Rate | C52: ='Assumptions & Data'!$B$93 -> 0.008 | D52: ='Assumptions & Data'!$B$93 -> 0.008 | E52: ='Assumptions & Data'!$B$93 -> 0.008 | F52: ='Assumptions & Data'!$B$93 -> 0.008 | G52: ='Assumptions & Data'!$B$93 -> 0.008 | H52: ='Assumptions & Data'!$B$93 -> 0.008 | I52: ='Assumptions & Data'!$B$93 -> 0.008 | J52: ='Assumptions & Data'!$B$93 -> 0.008 | ... P52: ='Assumptions & Data'!$B$93 -> 0.008 | Q52: =AVERAGE(E52:P52) -> 0.008
A53: Net Churn Rate | C53: ='Assumptions & Data'!B93-'Assumptions & Data'!B94 -> -0.004 | D53: ='Assumptions & Data'!C93-'Assumptions & Data'!C94 -> 0 | E53: ='Assumptions & Data'!D93-'Assumptions & Data'!D94 -> 0 | F53: ='Assumptions & Data'!E93-'Assumptions & Data'!E94 -> 0 | G53: ='Assumptions & Data'!F93-'Assumptions & Data'!F94 -> 0 | H53: ='Assumptions & Data'!G93-'Assumptions & Data'!G94 -> 0 | I53: ='Assumptions & Data'!H93-'Assumptions & Data'!H94 -> 0 | J53: ='Assumptions & Data'!I93-'Assumptions & Data'!I94 -> 0 | ... P53: ='Assumptions & Data'!O93-'Assumptions & Data'!O94 -> 0 | Q53: =AVERAGE(E53:P53) -> 0
...

Sheet Assumptions & Data
A2: Base Case | E2: Cases
D3: Base | E3: 1
A4: KEY ASSUMPTIONS & DRIVERS | D4: Downside | E4: 2
A5: Assumption | B5: Value | C5: Notes | D5: Upside | E5: 3
A6: Starting MRR (₹) | B6: 450000000 | C6: Current monthly recurring revenue | D6: =VLOOKUP('Exeutive Dashboard'!I3,'Assumptions & Data'!D3:E5,2,FALSE) -> 3
A7: Monthly New Customer Acquisition | B7: 25 | C7: New customers per month
A8: New Customer Growth Rate (MoM) | B8: 0.025 | C8: Monthly growth in new customers
A9: Average Revenue Per Account (ARPA) | B9: 600000 | C9: Monthly revenue per customer
A10: Monthly Gross Churn Rate | B10: 0.012 | C10: % customers lost per month
A11: Expansion Revenue Rate (MoM) | B11: 0.008 | C11: Upsell/expansion % of existing MRR
A12: Gross Margin % | B12: 0.72 | C12: After hosting & support costs
A13: Customer Acquisition Cost (CAC) | B13: 1800000 | C13: Blended cost to acquire customer
A14: Starting Cash Balance | B14: 2200000000 | C14: Post Series A cash
A15: Monthly Opex Growth Rate | B15: 0.015 | C15: Monthly operating expense growth
A16: Starting Customers | B16: 750 | C16: Current customer count
A17: Sales Cycle (months) | B17: 6 | C17: Average time to close deal
A19: OPERATING EXPENSES (MONTHLY)
A20: Expense Category | B20: Monthly (₹) | C20: Notes
A21: Engineering Salaries | B21: 95000000 | C21: 8 engineers @ ₹11.9K avg
A22: Sales & Marketing | B22: 120000000 | C22: Team + ad spend
A23: G&A (Admin, Legal, Finance) | B23: 35000000 | C23: Back office costs
A24: Customer Success | B24: 22000000 | C24: CS team salaries
A25: Infrastructure & Tools | B25: 18000000 | C25: AWS, software tools
A26: Office & Misc | B26: 12000000 | C26: Rent, utilities, misc
A27: Total Monthly OpEx | B27: =SUM(B21:B26) -> 302000000
A30: Downside case
A32: KEY ASSUMPTIONS & DRIVERS
A33: Assumption | B33: Value | C33: Notes
A34: Starting MRR (₹) | B34: 430000000 | C34: Current monthly recurring revenue
A35: Monthly New Customer Acquisition | B35: 15 | C35: New customers per month
A36: New Customer Growth Rate (MoM) | B36: 0.012 | C36: Monthly growth in new customers
A37: Average Revenue Per Account (ARPA) | B37: 550000 | C37: Monthly revenue per customer
A38: Monthly Gross Churn Rate | B38: 0.02 | C38: % customers lost per month
A39: Expansion Revenue Rate (MoM) | B39: 0.004 | C39: Upsell/expansion % of existing MRR
A40: Gross Margin % | B40: 0.68 | C40: After hosting & support costs
A41: Customer Acquisition Cost (CAC) | B41: 2000000 | C41: Blended cost to acquire customer
A42: Starting Cash Balance | B42: 2200000000 | C42: Post Series A cash
A43: Monthly Opex Growth Rate | B43: 0.008 | C43: Monthly operating expense growth
A44: Starting Customers | B44: 720 | C44: Current customer count
A45: Sales Cycle (months) | B45: 8 | C45: Average time to close deal
...

Sheet SaaS Financial Model
A1: 1
A3: KEY ASSUMPTIONS & DRIVERS | F3: EXECUTIVE DASHBOARD
A4: Assumption | B4: Value | C4: Notes | F4: Metric | G4: Current | H4: Month 12 | J4: Key Indicators | K4: Status
A5: Starting MRR ($) | B5: 50000 | C5: Current monthly recurring revenue | F5: MRR | G5: =B42 -> 62000 | H5: =M42 -> 266890.39 | J5: LTV:CAC Ratio | K5: =IF(N67>=3,"✓ Healthy",IF(N67>=1,"⚠ Needs Improvement","✗ Critical")) -> ⚠ Needs Improvement
A6: Monthly New Customer Acquisition | B6: 25 | C6: New customers per month | F6: ARR | G6: =B43 -> 744000 | H6: =M43 -> 3202684.7 | J6: Burn Multiple | K6: =IF(N59/N41<2,"✓ Efficient",IF(N59/N41<4,"⚠ Monitor","✗ High Burn")) -> ⚠ Monitor
A7: New Customer Growth Rate (MoM) | B7: 0.08 | C7: Monthly growth in new customers | F7: Customers | G7: =B34 -> 122 | H7: =M34 -> 475 | J7: Gross Margin | K7: =IF(N65>=0.7,"✓ Healthy",IF(N65>=0.5,"⚠ Low","✗ Critical")) -> ✓ Healthy
A8: Average Revenue Per Account (ARPA) | B8: 500 | C8: Monthly revenue per customer | F8: Monthly Burn | G8: =B59 -> 435400 | H8: =M59 -> 636994.34 | J8: Churn Rate | K8: =IF(N73<=0.02,"✓ Low",IF(N73<=0.05,"⚠ Moderate","✗ High")) -> ⚠ Moderate
A9: Monthly Gross Churn Rate | B9: 0.03 | C9: % customers lost per month | F9: Cash Balance | G9: =B57 -> 2564600 | H9: =M57 -> -3310447.6 | J9: Quick Ratio | K9: =IF(N75>=4,"✓ Strong",IF(N75>=2,"⚠ Moderate","✗ Weak")) -> ✓ Strong
A10: Expansion Revenue Rate (MoM) | B10: 0.02 | C10: Upsell/expansion % of existing MRR | F10: Runway (mos) | G10: =B77 -> 5.8902159 | H10: =M77 -> -5.1969811
A11: Gross Margin % | B11: 0.8 | C11: After hosting & support costs
A12: Customer Acquisition Cost (CAC) | B12: 8000 | C12: Blended cost to acquire customer | F12: Year 1 Summary | J12: Funding Trigger
A13: Starting Cash Balance | B13: 3000000 | C13: Post Series A cash | F13: Total Revenue | G13: =N46 -> 1827851.1 | J13: Raise needed when runway < 6 months
A14: Monthly Opex Growth Rate | B14: 0.03 | C14: Monthly operating expense growth | F14: Total EBITDA | G14: =N50 -> -2582447.6 | J14: Current Status: | K14: =IF(B77<6,"⚠ START FUNDRAISING NOW","✓ Runway OK") -> ⚠ START FUNDRAISING NOW
A15: Starting Customers | B15: 100 | C15: Current customer count | F15: Net Cash Used | G15: =N56 -> -6310447.6
A16: Sales Cycle (months) | B16: 2 | C16: Average time to close deal | F16: Avg Burn Multiple | G16: =N59/N41 -> 2.4245916
A18: OPERATING EXPENSES (MONTHLY)
A19: Expense Category | B19: Monthly ($) | C19: Notes
A20: Engineering Salaries | B20: 120000 | C20: 8 engineers @ $15K avg
A21: Sales & Marketing | B21: 80000 | C21: Team + ad spend
A22: G&A (Admin, Legal, Finance) | B22: 35000 | C22: Back office costs
A23: Customer Success | B23: 25000 | C23: CS team salaries
A24: Infrastructure & Tools | B24: 15000 | C24: AWS, software tools
A25: Office & Misc | B25: 10000 | C25: Rent, utilities, misc
A26: Total Monthly OpEx | B26: =SUM(B20:B25) -> 285000
A28: 24-MONTH FINANCIAL PROJECTION
B29: Month 1 | C29: Month 2 | D29: Month 3 | E29: Month 4 | F29: Month 5 | G29: Month 6 | H29: Month 7 | I29: Month 8 | J29: Month 9 | K29: Month 10 | L29: Month 11 | M29: Month 12 | N29: Year 1 Total
A30: CUSTOMER METRICS
A31: Beginning Customers | B31: =$B$15 -> 100 | C31: =B34 -> 122 | D31: =C34 -> 145 | E31: =D34 -> 170 | F31: =E34 -> 196 | G31: =F34 -> 223 | H31: =G34 -> 252 | I31: =H34 -> 283 | J31: =I34 -> 317 | ... M31: =L34 -> 431 | N31: -
A32: New Customers | B32: =$B$6 -> 25 | C32: =ROUND(B32*(1+$B$7),0) -> 27 | D32: =ROUND(C32*(1+$B$7),0) -> 29 | E32: =ROUND(D32*(1+$B$7),0) -> 31 | F32: =ROUND(E32*(1+$B$7),0) -> 33 | G32: =ROUND(F32*(1+$B$7),0) -> 36 | H32: =ROUND(G32*(1+$B$7),0) -> 39 | I32: =ROUND(H32*(1+$B$7),0) -> 42 | J32: =ROUND(I32*(1+$B$7),0) -> 45 | ... M32: =ROUND(L32*(1+$B$7),0) -> 57 | N32: =SUM(B32:M32) -> 466
A33: Churned Customers | B33: =-ROUND(B31*$B$9,0) -> -3 | C33: =-ROUND(C31*$B$9,0) -> -4 | D33: =-ROUND(D31*$B$9,0) -> -4 | E33: =-ROUND(E31*$B$9,0) -> -5 | F33: =-ROUND(F31*$B$9,0) -> -6 | G33: =-ROUND(G31*$B$9,0) -> -7 | H33: =-ROUND(H31*$B$9,0) -> -8 | I33: =-ROUND(I31*$B$9,0) -> -8 | ... M33: =-ROUND(M31*$B$9,0) -> -13 | N33: =SUM(B33:M33) -> -91
A34: Ending Customers | B34: =B31+B32+B33 -> 122 | C34: =C31+C32+C33 -> 145 | D34: =D31+D32+D33 -> 170 | E34: =E31+E32+E33 -> 196 | F34: =F31+F32+F33 -> 223 | G34: =G31+G32+G33 -> 252 | H34: =H31+H32+H33 -> 283 | I34: =I31+I32+I33 -> 317 | ... M34: =M31+M32+M33 -> 475 | N34: =M34 -> 475
A36: REVENUE METRICS
A37: Beginning MRR | B37: =$B$5 -> 50000 | C37: =B42 -> 62000 | D37: =C42 -> 74880 | E37: =D42 -> 88631.2 | F37: =E42 -> 103244.89 | G37: =F42 -> 118712.44 | H37: =G42 -> 135525.31 | I37: =H42 -> 153670.06 | J37: =I42 -> 173133.36 | ... M37: =L42 -> 240798.38 | N37: -
A38: New MRR | B38: =B32*$B$8 -> 12500 | C38: =C32*$B$8 -> 13500 | D38: =D32*$B$8 -> 14500 | E38: =E32*$B$8 -> 15500 | F38: =F32*$B$8 -> 16500 | G38: =G32*$B$8 -> 18000 | H38: =H32*$B$8 -> 19500 | I38: =I32*$B$8 -> 21000 | ... M38: =M32*$B$8 -> 28500 | N38: =SUM(B38:M38) -> 233000
A39: Expansion MRR | B39: =B37*$B$10 -> 1000 | C39: =C37*$B$10 -> 1240 | D39: =D37*$B$10 -> 1497.6 | E39: =E37*$B$10 -> 1772.624 | F39: =F37*$B$10 -> 2064.8978 | G39: =G37*$B$10 -> 2374.2488 | H39: =H37*$B$10 -> 2710.5063 | I39: =I37*$B$10 -> 3073.4012 | ... M39: =M37*$B$10 -> 4815.9675 | N39: =SUM(B39:M39) -> 32219.214
A40: Churned MRR | B40: =-B37*$B$9 -> -1500 | C40: =-C37*$B$9 -> -1860 | D40: =-D37*$B$9 -> -2246.4 | E40: =-E37*$B$9 -> -2658.936 | F40: =-F37*$B$9 -> -3097.3466 | G40: =-G37*$B$9 -> -3561.3732 | H40: =-H37*$B$9 -> -4065.7594 | I40: =-I37*$B$9 -> -4610.1018 | ... M40: =-M37*$B$9 -> -7223.9513 | N40: =SUM(B40:M40) -> -48328.82
A41: Net New MRR | B41: =B38+B39+B40 -> 12000 | C41: =C38+C39+C40 -> 12880 | D41: =D38+D39+D40 -> 13751.2 | E41: =E38+E39+E40 -> 14613.688 | F41: =F38+F39+F40 -> 15467.551 | G41: =G38+G39+G40 -> 16812.876 | H41: =H38+H39+H40 -> 18144.747 | I41: =I38+I39+I40 -> 19463.299 | ... M41: =M38+M39+M40 -> 26092.016 | N41: =SUM(B41:M41) -> 216890.39
A42: Ending MRR | B42: =B37+B41 -> 62000 | C42: =C37+C41 -> 74880 | D42: =D37+D41 -> 88631.2 | E42: =E37+E41 -> 103244.89 | F42: =F37+F41 -> 118712.44 | G42: =G37+G41 -> 135525.31 | H42: =H37+H41 -> 153670.06 | I42: =I37+I41 -> 173133.36 | ... M42: =M37+M41 -> 266890.39 | N42: =M42 -> 266890.39
A43: ARR | B43: =B42*12 -> 744000 | C43: =C42*12 -> 898560 | D43: =D42*12 -> 1063574.4 | E43: =E42*12 -> 1238938.7 | F43: =F42*12 -> 1424549.3 | G43: =G42*12 -> 1626303.8 | H43: =H42*12 -> 1844040.7 | I43: =I42*12 -> 2077600.3 | ... M43: =M42*12 -> 3202684.7 | N43: =M43 -> 3202684.7
A45: P&L SUMMARY
...

Sheet Year 2 Projection
A1: YEAR 2 PROJECTION (MONTHS 13-24) - POST SERIES B
A3: SERIES B FUNDING SCENARIO
A4: Assumption | B4: Value | C4: Notes
A5: Series B Raise | B5: 15000000 | C5: Target raise amount
A6: Pre-Money Valuation | B6: 45000000 | C6: ~14x forward ARR
A7: Dilution % | B7: =B5/(B5+B6) -> 0.25 | C7: Investor ownership
A8: New Customer Growth (Y2) | B8: 0.05 | C8: Slower growth rate (maturity)
A9: Churn Improvement | B9: 0.025 | C9: Improved retention efforts
A10: OpEx Growth Rate (Y2) | B10: 0.02 | C10: More efficient spending
A11: ARPA Growth | B11: 0.01 | C11: Pricing power/upsells
A12: CAC Efficiency Gain | B12: 0.95 | C12: 5% CAC reduction factor
A14: YEAR 2 MONTHLY PROJECTION
B15: Month 13 | C15: Month 14 | D15: Month 15 | E15: Month 16 | F15: Month 17 | G15: Month 18 | H15: Month 19 | I15: Month 20 | J15: Month 21 | K15: Month 22 | L15: Month 23 | M15: Month 24 | N15: Year 2 Total | O15: Cumulative
A16: CUSTOMER METRICS
A17: Beginning Customers | B17: ='SaaS Financial Model'!M34 -> 475 | C17: =B20 -> 523 | D17: =C20 -> 573 | E17: =D20 -> 625 | F17: =E20 -> 678 | G17: =F20 -> 733 | H17: =G20 -> 791 | I17: =H20 -> 851 | J17: =I20 -> 914 | ... M17: =L20 -> 1118 | N17: - | O17: -
A18: New Customers | B18: =ROUND('SaaS Financial Model'!M32*(1+$B$8),0) -> 60 | C18: =ROUND(B18*(1+$B$8),0) -> 63 | D18: =ROUND(C18*(1+$B$8),0) -> 66 | E18: =ROUND(D18*(1+$B$8),0) -> 69 | F18: =ROUND(E18*(1+$B$8),0) -> 72 | G18: =ROUND(F18*(1+$B$8),0) -> 76 | H18: =ROUND(G18*(1+$B$8),0) -> 80 | I18: =ROUND(H18*(1+$B$8),0) -> 84 | J18: =ROUND(I18*(1+$B$8),0) -> 88 | ... M18: =ROUND(L18*(1+$B$8),0) -> 102 | N18: =SUM(B18:M18) -> 949 | O18: =N18+'SaaS Financial Model'!N32 -> 1415
A19: Churned Customers | B19: =-ROUND(B17*$B$9,0) -> -12 | C19: =-ROUND(C17*$B$9,0) -> -13 | D19: =-ROUND(D17*$B$9,0) -> -14 | E19: =-ROUND(E17*$B$9,0) -> -16 | F19: =-ROUND(F17*$B$9,0) -> -17 | G19: =-ROUND(G17*$B$9,0) -> -18 | H19: =-ROUND(H17*$B$9,0) -> -20 | I19: =-ROUND(I17*$B$9,0) -> -21 | ... M19: =-ROUND(M17*$B$9,0) -> -28 | N19: =SUM(B19:M19) -> -232 | O19: =N19+'SaaS Financial Model'!N33 -> -323
A20: Ending Customers | B20: =B17+B18+B19 -> 523 | C20: =C17+C18+C19 -> 573 | D20: =D17+D18+D19 -> 625 | E20: =E17+E18+E19 -> 678 | F20: =F17+F18+F19 -> 733 | G20: =G17+G18+G19 -> 791 | H20: =H17+H18+H19 -> 851 | I20: =I17+I18+I19 -> 914 | ... M20: =M17+M18+M19 -> 1192 | N20: =M20 -> 1192 | O20: =M20 -> 1192
A22: REVENUE METRICS
A23: Beginning MRR | B23: ='SaaS Financial Model'!M42 -> 266890.39 | C23: =B28 -> 295855.94 | D23: =C28 -> 326191.66 | E23: =D28 -> 357890.7 | F23: =E28 -> 390946.25 | G23: =F28 -> 425351.52 | H23: =G28 -> 461604.76 | I23: =H28 -> 499696.74 | J23: =I28 -> 539618.25 | ... M23: =L28 -> 670773.79 | N23: - | O23: -
A24: New MRR | B24: =B18*'SaaS Financial Model'!$B$8*(1+$B$11) -> 30300 | C24: =C18*'SaaS Financial Model'!$B$8*(1+$B$11) -> 31815 | D24: =D18*'SaaS Financial Model'!$B$8*(1+$B$11) -> 33330 | E24: =E18*'SaaS Financial Model'!$B$8*(1+$B$11) -> 34845 | F24: =F18*'SaaS Financial Model'!$B$8*(1+$B$11) -> 36360 | G24: =G18*'SaaS Financial Model'!$B$8*(1+$B$11) -> 38380 | H24: =H18*'SaaS Financial Model'!$B$8*(1+$B$11) -> 40400 | I24: =I18*'SaaS Financial Model'!$B$8*(1+$B$11) -> 42420 | ... M24: =M18*'SaaS Financial Model'!$B$8*(1+$B$11) -> 51510 | N24: =SUM(B24:M24) -> 479245 | O24: =N24+'SaaS Financial Model'!N38 -> 712245
A25: Expansion MRR | B25: =B23*'SaaS Financial Model'!$B$10 -> 5337.8079 | C25: =C23*'SaaS Financial Model'!$B$10 -> 5917.1188 | D25: =D23*'SaaS Financial Model'!$B$10 -> 6523.8332 | E25: =E23*'SaaS Financial Model'!$B$10 -> 7157.8141 | F25: =F23*'SaaS Financial Model'!$B$10 -> 7818.925 | G25: =G23*'SaaS Financial Model'!$B$10 -> 8507.0304 | H25: =H23*'SaaS Financial Model'!$B$10 -> 9232.0952 | I25: =I23*'SaaS Financial Model'!$B$10 -> 9993.9347 | ... M25: =M23*'SaaS Financial Model'!$B$10 -> 13415.476 | N25: =SUM(B25:M25) -> 108821.87 | O25: =N25+'SaaS Financial Model'!N39 -> 141041.08
A26: Churned MRR | B26: =-B23*$B$9 -> -6672.2598 | C26: =-C23*$B$9 -> -7396.3985 | D26: =-D23*$B$9 -> -8154.7915 | E26: =-E23*$B$9 -> -8947.2676 | F26: =-F23*$B$9 -> -9773.6562 | G26: =-G23*$B$9 -> -10633.788 | H26: =-H23*$B$9 -> -11540.119 | I26: =-I23*$B$9 -> -12492.418 | ... M26: =-M23*$B$9 -> -16769.345 | N26: =SUM(B26:M26) -> -136027.34 | O26: =N26+'SaaS Financial Model'!N40 -> -184356.16
A27: Net New MRR | B27: =B24+B25+B26 -> 28965.548 | C27: =C24+C25+C26 -> 30335.72 | D27: =D24+D25+D26 -> 31699.042 | E27: =E24+E25+E26 -> 33055.546 | F27: =F24+F25+F26 -> 34405.269 | G27: =G24+G25+G26 -> 36253.242 | H27: =H24+H25+H26 -> 38091.976 | I27: =I24+I25+I26 -> 39921.516 | ... M27: =M24+M25+M26 -> 48156.131 | N27: =SUM(B27:M27) -> 452039.53 | O27: =N27+'SaaS Financial Model'!N41 -> 668929.93
A28: Ending MRR | B28: =B23+B27 -> 295855.94 | C28: =C23+C27 -> 326191.66 | D28: =D23+D27 -> 357890.7 | E28: =E23+E27 -> 390946.25 | F28: =F23+F27 -> 425351.52 | G28: =G23+G27 -> 461604.76 | H28: =H23+H27 -> 499696.74 | I28: =I23+I27 -> 539618.25 | ... M28: =M23+M27 -> 718929.93 | N28: =M28 -> 718929.93 | O28: =M28 -> 718929.93
A29: ARR | B29: =B28*12 -> 3550271.3 | C29: =C28*12 -> 3914299.9 | D29: =D28*12 -> 4294688.4 | E29: =E28*12 -> 4691355 | F29: =F28*12 -> 5104218.2 | G29: =G28*12 -> 5539257.1 | H29: =H28*12 -> 5996360.8 | I29: =I28*12 -> 6475419 | ... M29: =M28*12 -> 8627159.1 | N29: =M29 -> 8627159.1 | O29: =M29 -> 8627159.1
A31: P&L SUMMARY
A32: Revenue (MRR) | B32: =B28 -> 295855.94 | C32: =C28 -> 326191.66 | D32: =D28 -> 357890.7 | E32: =E28 -> 390946.25 | F32: =F28 -> 425351.52 | G32: =G28 -> 461604.76 | H32: =H28 -> 499696.74 | I32: =I28 -> 539618.25 | ... M32: =M28 -> 718929.93 | N32: =SUM(B32:M32) -> 5893133.1 | O32: =N32+'SaaS Financial Model'!N46 -> 7720984.1
A33: Cost of Revenue (COGS) | B33: =-B32*(1-'SaaS Financial Model'!$B$11) -> -59171.188 | C33: =-C32*(1-'SaaS Financial Model'!$B$11) -> -65238.332 | D33: =-D32*(1-'SaaS Financial Model'!$B$11) -> -71578.141 | E33: =-E32*(1-'SaaS Financial Model'!$B$11) -> -78189.25 | F33: =-F32*(1-'SaaS Financial Model'!$B$11) -> -85070.304 | G33: =-G32*(1-'SaaS Financial Model'!$B$11) -> -92320.952 | H33: =-H32*(1-'SaaS Financial Model'!$B$11) -> -99939.347 | I33: =-I32*(1-'SaaS Financial Model'!$B$11) -> -107923.65 | ... M33: =-M32*(1-'SaaS Financial Model'!$B$11) -> -143785.99 | N33: =SUM(B33:M33) -> -1178626.6 | O33: =N33+'SaaS Financial Model'!N47 -> -1544196.8
A34: Gross Profit | B34: =B32+B33 -> 236684.75 | C34: =C32+C33 -> 260953.33 | D34: =D32+D33 -> 286312.56 | E34: =E32+E33 -> 312757 | F34: =F32+F33 -> 340281.21 | G34: =G32+G33 -> 369283.81 | H34: =H32+H33 -> 399757.39 | I34: =I32+I33 -> 431694.6 | ... M34: =M32+M33 -> 575143.94 | N34: =SUM(B34:M34) -> 4714506.5 | O34: =N34+'SaaS Financial Model'!N48 -> 6176787.3
A35: Operating Expenses | B35: ='SaaS Financial Model'!M49*(1+$B$10) -> -402396.79 | C35: =B35*(1+$B$10) -> -410444.72 | D35: =C35*(1+$B$10) -> -418653.62 | E35: =D35*(1+$B$10) -> -427026.69 | F35: =E35*(1+$B$10) -> -435567.22 | G35: =F35*(1+$B$10) -> -444278.57 | H35: =G35*(1+$B$10) -> -453164.14 | I35: =H35*(1+$B$10) -> -462227.42 | J35: =I35*(1+$B$10) -> -471471.97 | ... M35: =L35*(1+$B$10) -> -500329.83 | N35: =SUM(B35:M35) -> -5396981.8 | O35: =N35+'SaaS Financial Model'!N49 -> -9441710.2
A36: EBITDA | B36: =B34+B35 -> -165712.03 | C36: =C34+C35 -> -149491.39 | D36: =D34+D35 -> -132341.05 | E36: =E34+E35 -> -114269.69 | F36: =F34+F35 -> -95286.008 | G36: =G34+G35 -> -74994.758 | H36: =H34+H35 -> -53406.749 | I36: =I34+I35 -> -30532.818 | ... M36: =M34+M35 -> 74814.115 | N36: =SUM(B36:M36) -> -682475.35 | O36: =N36+'SaaS Financial Model'!N50 -> -3264922.9
A38: CASH FLOW & RUNWAY
A39: Beginning Cash | B39: ='SaaS Financial Model'!M57 -> -3310447.6 | C39: =B44 -> 11067840 | D39: =C44 -> 10439549 | E39: =D44 -> 9805608 | F39: =E44 -> 9166938.3 | G39: =F44 -> 8524452.3 | H39: =G44 -> 7871857.5 | I39: =H44 -> 7210450.7 | J39: =I44 -> 6541517.9 | ... M39: =L44 -> 4495063
A40: Series B Funding | B40: =$B$5 -> 15000000 | C40: 0 | D40: 0 | E40: 0 | F40: 0 | G40: 0 | H40: 0 | I40: 0 | J40: 0 | K40: 0 | L40: 0 | M40: 0
A41: Cash from Operations (EBITDA) | B41: =B36 -> -165712.03 | C41: =C36 -> -149491.39 | D41: =D36 -> -132341.05 | E41: =E36 -> -114269.69 | F41: =F36 -> -95286.008 | G41: =G36 -> -74994.758 | H41: =H36 -> -53406.749 | I41: =I36 -> -30532.818 | ... M41: =M36 -> 74814.115
A42: CAC Investment | B42: =-B18*'SaaS Financial Model'!$B$12*$B$12 -> -456000 | C42: =-C18*'SaaS Financial Model'!$B$12*$B$12 -> -478800 | D42: =-D18*'SaaS Financial Model'!$B$12*$B$12 -> -501600 | E42: =-E18*'SaaS Financial Model'!$B$12*$B$12 -> -524400 | F42: =-F18*'SaaS Financial Model'!$B$12*$B$12 -> -547200 | G42: =-G18*'SaaS Financial Model'!$B$12*$B$12 -> -577600 | H42: =-H18*'SaaS Financial Model'!$B$12*$B$12 -> -608000 | I42: =-I18*'SaaS Financial Model'!$B$12*$B$12 -> -638400 | ... M42: =-M18*'SaaS Financial Model'!$B$12*$B$12 -> -775200
A43: Net Cash Flow | B43: =B40+B41+B42 -> 14378288 | C43: =C40+C41+C42 -> -628291.39 | D43: =D40+D41+D42 -> -633941.05 | E43: =E40+E41+E42 -> -638669.69 | F43: =F40+F41+F42 -> -642486.01 | G43: =G40+G41+G42 -> -652594.76 | H43: =H40+H41+H42 -> -661406.75 | I43: =I40+I41+I42 -> -668932.82 | ... M43: =M40+M41+M42 -> -700385.89
A44: Ending Cash | B44: =B39+B43 -> 11067840 | C44: =C39+C43 -> 10439549 | D44: =D39+D43 -> 9805608 | E44: =E39+E43 -> 9166938.3 | F44: =F39+F43 -> 8524452.3 | G44: =G39+G43 -> 7871857.5 | H44: =H39+H43 -> 7210450.7 | I44: =I39+I43 -> 6541517.9 | ... M44: =M39+M43 -> 3794677.1
A46: Monthly Burn Rate
...
